Workbook

Sheet Dashboard
B1: LEAD MANAGEMENT & SALES PIPELINE DASHBOARD
B2: ="Reporting date: "&TEXT(Settings!$C$3,"dd mmm yyyy")&" | Sample data | Source: Lead_Data sheet (CRM / ERP lead export)" -> Reporting date: 19 Oct 2026 | Sample data | Source: Lead_Data sheet (CRM / ERP lead export)
B3: Sales Executive: | D3: All | G3: <- pick an executive from the drop-down; KPIs, charts and Top 10 update (scorecard always shows everyone)
B5: Total Leads | E5: Won Deals | H5: Lost Leads | K5: Open Leads | N5: Conversion Rate
B6: =Analysis!B5 -> 320 | E6: =Analysis!B6 -> 74 | H6: =Analysis!B7 -> 82 | K6: =Analysis!B8 -> 164 | N6: =Analysis!B9 -> 0.23125
B8: Open Pipeline (AED) | E8: Won Value (AED) | H8: Avg Response (hrs) | K8: Follow-up Compliance | N8: Needs Attention
B9: =Analysis!B10 -> 7671200 | E9: =Analysis!B11 -> 2906100 | H9: =Analysis!B12 -> 8.176699 | K9: =Analysis!B13 -> 0.53658537 | N9: =Analysis!B17 -> 76
B43: SALES EXECUTIVE SCORECARD
B44: Executive | D44: Leads | E44: Won | F44: Lost | G44: Open | H44: Conv % | I44: Won Value (AED) | K44: Pipeline (AED) | M44: Avg Resp (hrs) | N44: Overdue | O44: Inactive | P44: Compliance
B45: =Analysis!A76 -> Rahul Menon | D45: =Analysis!B76 -> 53 | E45: =Analysis!C76 -> 14 | F45: =Analysis!D76 -> 17 | G45: =Analysis!E76 -> 22 | H45: =Analysis!F76 -> 0.26415094 | I45: =Analysis!G76 -> 345800 | K45: =Analysis!H76 -> 900100 | M45: =Analysis!I76 -> 6.0339623 | N45: =Analysis!J76 -> 10 | O45: =Analysis!K76 -> 1 | P45: =Analysis!L76 -> 0.5
B46: =Analysis!A77 -> Fatima Khan | D46: =Analysis!B77 -> 43 | E46: =Analysis!C77 -> 10 | F46: =Analysis!D77 -> 11 | G46: =Analysis!E77 -> 22 | H46: =Analysis!F77 -> 0.23255814 | I46: =Analysis!G77 -> 430400 | K46: =Analysis!H77 -> 1248800 | M46: =Analysis!I77 -> 7.1707317 | N46: =Analysis!J77 -> 6 | O46: =Analysis!K77 -> 0 | P46: =Analysis!L77 -> 0.72727273
B47: =Analysis!A78 -> Omar Siddiqui | D47: =Analysis!B78 -> 51 | E47: =Analysis!C78 -> 11 | F47: =Analysis!D78 -> 9 | G47: =Analysis!E78 -> 31 | H47: =Analysis!F78 -> 0.21568627 | I47: =Analysis!G78 -> 291300 | K47: =Analysis!H78 -> 1131600 | M47: =Analysis!I78 -> 13.864 | N47: =Analysis!J78 -> 11 | O47: =Analysis!K78 -> 0 | P47: =Analysis!L78 -> 0.64516129
B48: =Analysis!A79 -> Priya Nair | D48: =Analysis!B79 -> 56 | E48: =Analysis!C79 -> 15 | F48: =Analysis!D79 -> 12 | G48: =Analysis!E79 -> 29 | H48: =Analysis!F79 -> 0.26785714 | I48: =Analysis!G79 -> 804700 | K48: =Analysis!H79 -> 1346100 | M48: =Analysis!I79 -> 5.4036364 | N48: =Analysis!J79 -> 14 | O48: =Analysis!K79 -> 1 | P48: =Analysis!L79 -> 0.48275862
B49: =Analysis!A80 -> Ahmed Hassan | D49: =Analysis!B80 -> 53 | E49: =Analysis!C80 -> 9 | F49: =Analysis!D80 -> 16 | G49: =Analysis!E80 -> 28 | H49: =Analysis!F80 -> 0.16981132 | I49: =Analysis!G80 -> 367200 | K49: =Analysis!H80 -> 1063900 | M49: =Analysis!I80 -> 10.081132 | N49: =Analysis!J80 -> 15 | O49: =Analysis!K80 -> 1 | P49: =Analysis!L80 -> 0.42857143
B50: =Analysis!A81 -> Sara Thomas | D50: =Analysis!B81 -> 57 | E50: =Analysis!C81 -> 15 | F50: =Analysis!D81 -> 17 | G50: =Analysis!E81 -> 25 | H50: =Analysis!F81 -> 0.26315789 | I50: =Analysis!G81 -> 666700 | K50: =Analysis!H81 -> 1663000 | M50: =Analysis!I81 -> 6.8087719 | N50: =Analysis!J81 -> 10 | O50: =Analysis!K81 -> 0 | P50: =Analysis!L81 -> 0.6
B51: =Analysis!A82 -> Unassigned | D51: =Analysis!B82 -> 7 | E51: =Analysis!C82 -> 0 | F51: =Analysis!D82 -> 0 | G51: =Analysis!E82 -> 7 | H51: =Analysis!F82 -> 0 | I51: =Analysis!G82 -> 0 | K51: =Analysis!H82 -> 317700 | M51: =Analysis!I82 -> 0 | N51: =Analysis!J82 -> 0 | O51: =Analysis!K82 -> 0 | P51: =Analysis!L82 -> 0
B52: =Analysis!A83 -> Total | D52: =Analysis!B83 -> 320 | E52: =Analysis!C83 -> 74 | F52: =Analysis!D83 -> 82 | G52: =Analysis!E83 -> 164 | H52: =Analysis!F83 -> 0.23125 | I52: =Analysis!G83 -> 2906100 | K52: =Analysis!H83 -> 7671200 | M52: =Analysis!I83 -> 8.176699 | N52: =Analysis!J83 -> 66 | O52: =Analysis!K83 -> 3 | P52: =Analysis!L83 -> 0.53658537
B55: TOP 10 HIGH-VALUE OPEN LEADS (follow the Executive filter)
B56: Rank | C56: Lead ID | D56: Customer | G56: Executive | I56: Stage | K56: Value (AED) | M56: Days Since Contact | N56: Follow-up Status | P56: Source
B57: =Analysis!A89 -> 1 | C57: =Analysis!D89 -> L-0192 | D57: =Analysis!E89 -> Union Construction | G57: =Analysis!F89 -> Sara Thomas | I57: =Analysis!G89 -> Negotiation | K57: =Analysis!H89 -> 371900 | M57: =Analysis!I89 -> 8 | N57: =Analysis!J89 -> Overdue | P57: =Analysis!K89 -> LinkedIn
B58: =Analysis!A90 -> 2 | C58: =Analysis!D90 -> L-0131 | D58: =Analysis!E90 -> Falcon Technical Services | G58: =Analysis!F90 -> Fatima Khan | I58: =Analysis!G90 -> Negotiation | K58: =Analysis!H90 -> 331500 | M58: =Analysis!I90 -> 3 | N58: =Analysis!J90 -> On Track | P58: =Analysis!K90 -> Exhibition
B59: =Analysis!A91 -> 3 | C59: =Analysis!D91 -> L-0035 | D59: =Analysis!E91 -> Sahara Engineering | G59: =Analysis!F91 -> Priya Nair | I59: =Analysis!G91 -> Negotiation | K59: =Analysis!H91 -> 293300 | M59: =Analysis!I91 -> 18 | N59: =Analysis!J91 -> Overdue | P59: =Analysis!K91 -> Website
B60: =Analysis!A92 -> 4 | C60: =Analysis!D92 -> L-0017 | D60: =Analysis!E92 -> Skyline Construction | G60: =Analysis!F92 -> Fatima Khan | I60: =Analysis!G92 -> Quotation Sent | K60: =Analysis!H92 -> 225700 | M60: =Analysis!I92 -> 2 | N60: =Analysis!J92 -> On Track | P60: =Analysis!K92 -> Phone Call
B61: =Analysis!A93 -> 5 | C61: =Analysis!D93 -> L-0022 | D61: =Analysis!E93 -> Prime Technical Services | G61: =Analysis!F93 -> Sara Thomas | I61: =Analysis!G93 -> Quotation Sent | K61: =Analysis!H93 -> 177700 | M61: =Analysis!I93 -> 5 | N61: =Analysis!J93 -> Overdue | P61: =Analysis!K93 -> WhatsApp
B62: =Analysis!A94 -> 6 | C62: =Analysis!D94 -> L-0225 | D62: =Analysis!E94 -> Horizon Industries | G62: =Analysis!F94 -> Priya Nair | I62: =Analysis!G94 -> Negotiation | K62: =Analysis!H94 -> 174200 | M62: =Analysis!I94 -> 2 | N62: =Analysis!J94 -> On Track | P62: =Analysis!K94 -> Email
B63: =Analysis!A95 -> 7 | C63: =Analysis!D95 -> L-0286 | D63: =Analysis!E95 -> Desert Construction | G63: =Analysis!F95 -> Unassigned | I63: =Analysis!G95 -> New | K63: =Analysis!H95 -> 163600 | M63: =Analysis!I95 -> 11 | N63: =Analysis!J95 -> Unassigned | P63: =Analysis!K95 -> Exhibition
B64: =Analysis!A96 -> 8 | C64: =Analysis!D96 -> L-0233 | D64: =Analysis!E96 -> Emirates Construction | G64: =Analysis!F96 -> Rahul Menon | I64: =Analysis!G96 -> Contacted | K64: =Analysis!H96 -> 158200 | M64: =Analysis!I96 -> 25 | N64: =Analysis!J96 -> Overdue | P64: =Analysis!K96 -> Email
B65: =Analysis!A97 -> 9 | C65: =Analysis!D97 -> L-0011 | D65: =Analysis!E97 -> Emirates Industries | G65: =Analysis!F97 -> Sara Thomas | I65: =Analysis!G97 -> Quotation Sent | K65: =Analysis!H97 -> 153400 | M65: =Analysis!I97 -> 2 | N65: =Analysis!J97 -> On Track | P65: =Analysis!K97 -> Walk-in
B66: =Analysis!A98 -> 10 | C66: =Analysis!D98 -> L-0229 | D66: =Analysis!E98 -> Emirates Construction | G66: =Analysis!F98 -> Priya Nair | I66: =Analysis!G98 -> Quotation Sent | K66: =Analysis!H98 -> 123800 | M66: =Analysis!I98 -> 3 | N66: =Analysis!J98 -> On Track | P66: =Analysis!K98 -> Website
B68: Definitions: Conversion = Won / Total leads | Compliance = On-Track open leads / Open leads | Overdue = next follow-up date passed | Inactive = no contact for the threshold in Settings | Needs Attention = Overdue + Inactive + Unassigned.

Sheet Analysis
A1: Analysis
A2: Executive filter criterion | B2: =IF(Dashboard!$D$3="All","*",Dashboard!$D$3) -> *
A4: KPIs (follow the Executive filter)
A5: Total Leads | B5: =COUNTIFS(Lead_Data!$F$2:$F$600,$B$2) -> 320
A6: Won Deals | B6: =COUNTIFS(Lead_Data!$F$2:$F$600,$B$2,Lead_Data!$G$2:$G$600,"Won") -> 74
A7: Lost Leads | B7: =COUNTIFS(Lead_Data!$F$2:$F$600,$B$2,Lead_Data!$G$2:$G$600,"Lost") -> 82
A8: Open Leads | B8: =COUNTIFS(Lead_Data!$F$2:$F$600,$B$2,Lead_Data!$O$2:$O$600,"Open") -> 164
A9: Conversion Rate | B9: =IFERROR(B6/B5,0) -> 0.23125
A10: Open Pipeline Value (AED) | B10: =SUMIFS(Lead_Data!$H$2:$H$600,Lead_Data!$F$2:$F$600,$B$2,Lead_Data!$O$2:$O$600,"Open") -> 7671200
A11: Won Value (AED) | B11: =SUMIFS(Lead_Data!$H$2:$H$600,Lead_Data!$F$2:$F$600,$B$2,Lead_Data!$G$2:$G$600,"Won") -> 2906100
A12: Avg Response Time (hrs) | B12: =IFERROR(AVERAGEIFS(Lead_Data!$N$2:$N$600,Lead_Data!$F$2:$F$600,$B$2),0) -> 8.176699
A13: Follow-up Compliance | B13: =IFERROR(COUNTIFS(Lead_Data!$F$2:$F$600,$B$2,Lead_Data!$R$2:$R$600,"On Track")/B8,0) -> 0.53658537
A14: Overdue Follow-ups | B14: =COUNTIFS(Lead_Data!$F$2:$F$600,$B$2,Lead_Data!$R$2:$R$600,"Overdue") -> 66
A15: Inactive Leads | B15: =COUNTIFS(Lead_Data!$F$2:$F$600,$B$2,Lead_Data!$R$2:$R$600,"Inactive") -> 3
A16: Unassigned Leads | B16: =COUNTIFS(Lead_Data!$F$2:$F$600,$B$2,Lead_Data!$R$2:$R$600,"Unassigned") -> 7
A17: Needs Attention (Overdue+Inactive+Unassigned) | B17: =B14+B15+B16 -> 76
A20: Pipeline by Stage
A21: Stage | B21: Leads | C21: Value (AED)
A22: New | B22: =COUNTIFS(Lead_Data!$F$2:$F$600,$B$2,Lead_Data!$G$2:$G$600,A22) -> 11 | C22: =SUMIFS(Lead_Data!$H$2:$H$600,Lead_Data!$F$2:$F$600,$B$2,Lead_Data!$G$2:$G$600,A22) -> 445200
A23: Contacted | B23: =COUNTIFS(Lead_Data!$F$2:$F$600,$B$2,Lead_Data!$G$2:$G$600,A23) -> 49 | C23: =SUMIFS(Lead_Data!$H$2:$H$600,Lead_Data!$F$2:$F$600,$B$2,Lead_Data!$G$2:$G$600,A23) -> 1899700
A24: Quotation Sent | B24: =COUNTIFS(Lead_Data!$F$2:$F$600,$B$2,Lead_Data!$G$2:$G$600,A24) -> 64 | C24: =SUMIFS(Lead_Data!$H$2:$H$600,Lead_Data!$F$2:$F$600,$B$2,Lead_Data!$G$2:$G$600,A24) -> 2788100
A25: Negotiation | B25: =COUNTIFS(Lead_Data!$F$2:$F$600,$B$2,Lead_Data!$G$2:$G$600,A25) -> 40 | C25: =SUMIFS(Lead_Data!$H$2:$H$600,Lead_Data!$F$2:$F$600,$B$2,Lead_Data!$G$2:$G$600,A25) -> 2538200
A26: Won | B26: =COUNTIFS(Lead_Data!$F$2:$F$600,$B$2,Lead_Data!$G$2:$G$600,A26) -> 74 | C26: =SUMIFS(Lead_Data!$H$2:$H$600,Lead_Data!$F$2:$F$600,$B$2,Lead_Data!$G$2:$G$600,A26) -> 2906100
A27: Lost | B27: =COUNTIFS(Lead_Data!$F$2:$F$600,$B$2,Lead_Data!$G$2:$G$600,A27) -> 82 | C27: =SUMIFS(Lead_Data!$H$2:$H$600,Lead_Data!$F$2:$F$600,$B$2,Lead_Data!$G$2:$G$600,A27) -> 3766800
A30: Monthly Lead Trend
A31: Month | B31: Label | C31: Leads Received | D31: Won | E31: Lost
A32: =DATE(2026,6,1) -> 46174 | B32: =TEXT(A32,"mmm-yy") -> Jun-26 | C32: =COUNTIFS(Lead_Data!$F$2:$F$600,$B$2,Lead_Data!$T$2:$T$600,$A32) -> 62 | D32: =COUNTIFS(Lead_Data!$F$2:$F$600,$B$2,Lead_Data!$T$2:$T$600,$A32,Lead_Data!$G$2:$G$600,"Won") -> 25 | E32: =COUNTIFS(Lead_Data!$F$2:$F$600,$B$2,Lead_Data!$T$2:$T$600,$A32,Lead_Data!$G$2:$G$600,"Lost") -> 22
A33: =EDATE(A32,1) -> 46204 | B33: =TEXT(A33,"mmm-yy") -> Jul-26 | C33: =COUNTIFS(Lead_Data!$F$2:$F$600,$B$2,Lead_Data!$T$2:$T$600,$A33) -> 55 | D33: =COUNTIFS(Lead_Data!$F$2:$F$600,$B$2,Lead_Data!$T$2:$T$600,$A33,Lead_Data!$G$2:$G$600,"Won") -> 17 | E33: =COUNTIFS(Lead_Data!$F$2:$F$600,$B$2,Lead_Data!$T$2:$T$600,$A33,Lead_Data!$G$2:$G$600,"Lost") -> 21
A34: =EDATE(A33,1) -> 46235 | B34: =TEXT(A34,"mmm-yy") -> Aug-26 | C34: =COUNTIFS(Lead_Data!$F$2:$F$600,$B$2,Lead_Data!$T$2:$T$600,$A34) -> 67 | D34: =COUNTIFS(Lead_Data!$F$2:$F$600,$B$2,Lead_Data!$T$2:$T$600,$A34,Lead_Data!$G$2:$G$600,"Won") -> 15 | E34: =COUNTIFS(Lead_Data!$F$2:$F$600,$B$2,Lead_Data!$T$2:$T$600,$A34,Lead_Data!$G$2:$G$600,"Lost") -> 20
A35: =EDATE(A34,1) -> 46266 | B35: =TEXT(A35,"mmm-yy") -> Sep-26 | C35: =COUNTIFS(Lead_Data!$F$2:$F$600,$B$2,Lead_Data!$T$2:$T$600,$A35) -> 79 | D35: =COUNTIFS(Lead_Data!$F$2:$F$600,$B$2,Lead_Data!$T$2:$T$600,$A35,Lead_Data!$G$2:$G$600,"Won") -> 13 | E35: =COUNTIFS(Lead_Data!$F$2:$F$600,$B$2,Lead_Data!$T$2:$T$600,$A35,Lead_Data!$G$2:$G$600,"Lost") -> 15
A36: =EDATE(A35,1) -> 46296 | B36: =TEXT(A36,"mmm-yy") -> Oct-26 | C36: =COUNTIFS(Lead_Data!$F$2:$F$600,$B$2,Lead_Data!$T$2:$T$600,$A36) -> 57 | D36: =COUNTIFS(Lead_Data!$F$2:$F$600,$B$2,Lead_Data!$T$2:$T$600,$A36,Lead_Data!$G$2:$G$600,"Won") -> 4 | E36: =COUNTIFS(Lead_Data!$F$2:$F$600,$B$2,Lead_Data!$T$2:$T$600,$A36,Lead_Data!$G$2:$G$600,"Lost") -> 4
A40: Open Lead Ageing
A41: Bucket | B41: Open Leads | C41: Value (AED)
A42: 0-7 days | B42: =COUNTIFS(Lead_Data!$F$2:$F$600,$B$2,Lead_Data!$S$2:$S$600,A42) -> 26 | C42: =SUMIFS(Lead_Data!$H$2:$H$600,Lead_Data!$F$2:$F$600,$B$2,Lead_Data!$S$2:$S$600,A42) -> 1071100
A43: 8-15 days | B43: =COUNTIFS(Lead_Data!$F$2:$F$600,$B$2,Lead_Data!$S$2:$S$600,A43) -> 15 | C43: =SUMIFS(Lead_Data!$H$2:$H$600,Lead_Data!$F$2:$F$600,$B$2,Lead_Data!$S$2:$S$600,A43) -> 612100
A44: 16-30 days | B44: =COUNTIFS(Lead_Data!$F$2:$F$600,$B$2,Lead_Data!$S$2:$S$600,A44) -> 41 | C44: =SUMIFS(Lead_Data!$H$2:$H$600,Lead_Data!$F$2:$F$600,$B$2,Lead_Data!$S$2:$S$600,A44) -> 1832200
A45: 31-60 days | B45: =COUNTIFS(Lead_Data!$F$2:$F$600,$B$2,Lead_Data!$S$2:$S$600,A45) -> 35 | C45: =SUMIFS(Lead_Data!$H$2:$H$600,Lead_Data!$F$2:$F$600,$B$2,Lead_Data!$S$2:$S$600,A45) -> 1606100
A46: 60+ days | B46: =COUNTIFS(Lead_Data!$F$2:$F$600,$B$2,Lead_Data!$S$2:$S$600,A46) -> 47 | C46: =SUMIFS(Lead_Data!$H$2:$H$600,Lead_Data!$F$2:$F$600,$B$2,Lead_Data!$S$2:$S$600,A46) -> 2549700
A50: Lead Source Performance
A51: Source | B51: Leads | C51: Won | D51: Conversion % | E51: Won Value (AED)
...

Sheet Lead_Data
A1: Lead ID | B1: Date Received | C1: Lead Source | D1: Customer | E1: Requirement | F1: Assigned Executive | G1: Status | H1: Lead Value (AED) | I1: First Response | J1: Last Follow-up | K1: Next Follow-up | L1: Closure Date | M1: Lost Reason | N1: Response Time (hrs) | O1: Open / Closed | P1: Lead Age (days) | Q1: Days Since Last Contact | R1: Follow-up Status | S1: Ageing Bucket | T1: Month | U1: Priority Score
A2: L-0001 | B2: 46174.597 | C2: WhatsApp | D2: Oasis Construction | E2: Electrical Items | F2: Priya Nair | G2: Won | H2: 35900 | I2: 46174.656 | J2: 46212 | L2: 46212 | N2: =IF(OR($A2="",$I2=""),"",ROUND(($I2-$B2)*24,1)) -> 1.4 | O2: =IF($A2="","",IF(OR($G2="Won",$G2="Lost"),"Closed","Open")) -> Closed | P2: =IF($A2="","",IF($L2<>"",$L2,Settings!$C$3)-INT($B2)) -> 38 | Q2: =IF($O2<>"Open","",Settings!$C$3-IF($J2<>"",$J2,INT($B2))) | R2: =IF($A2="","",IF($O2="Closed","Closed",IF($F2="Unassigned","Unassigned",IF(AND($K2<>"",$K2<Settings!$C$3),"Overdue",IF($Q2>=Settings!$C$4,"Inactive","On Track"))))) -> Closed | S2: =IF($O2<>"Open","",IF($P2<=7,"0-7 days",IF($P2<=15,"8-15 days",IF($P2<=30,"16-30 days",IF($P2<=60,"31-60 days","60+ days"))))) | T2: =IF($A2="","",DATE(YEAR($B2),MONTH($B2),1)) -> 46174 | U2: =IF(AND($O2="Open",OR(Dashboard!$D$3="All",$F2=Dashboard!$D$3)),$H2+ROW()/100000,0) -> 0
A3: L-0002 | B3: 46175.396 | C3: Website | D3: Sahara Construction | E3: Office Supplies | F3: Fatima Khan | G3: Won | H3: 28300 | I3: 46175.6 | J3: 46182 | L3: 46182 | N3: =IF(OR($A3="",$I3=""),"",ROUND(($I3-$B3)*24,1)) -> 4.9 | O3: =IF($A3="","",IF(OR($G3="Won",$G3="Lost"),"Closed","Open")) -> Closed | P3: =IF($A3="","",IF($L3<>"",$L3,Settings!$C$3)-INT($B3)) -> 7 | Q3: =IF($O3<>"Open","",Settings!$C$3-IF($J3<>"",$J3,INT($B3))) | R3: =IF($A3="","",IF($O3="Closed","Closed",IF($F3="Unassigned","Unassigned",IF(AND($K3<>"",$K3<Settings!$C$3),"Overdue",IF($Q3>=Settings!$C$4,"Inactive","On Track"))))) -> Closed | S3: =IF($O3<>"Open","",IF($P3<=7,"0-7 days",IF($P3<=15,"8-15 days",IF($P3<=30,"16-30 days",IF($P3<=60,"31-60 days","60+ days"))))) | T3: =IF($A3="","",DATE(YEAR($B3),MONTH($B3),1)) -> 46174 | U3: =IF(AND($O3="Open",OR(Dashboard!$D$3="All",$F3=Dashboard!$D$3)),$H3+ROW()/100000,0) -> 0
A4: L-0003 | B4: 46175.41 | C4: Phone Call | D4: Apex Projects LLC | E4: Industrial Supplies | F4: Sara Thomas | G4: Won | H4: 67900 | I4: 46175.801 | J4: 46196 | L4: 46196 | N4: =IF(OR($A4="",$I4=""),"",ROUND(($I4-$B4)*24,1)) -> 9.4 | O4: =IF($A4="","",IF(OR($G4="Won",$G4="Lost"),"Closed","Open")) -> Closed | P4: =IF($A4="","",IF($L4<>"",$L4,Settings!$C$3)-INT($B4)) -> 21 | Q4: =IF($O4<>"Open","",Settings!$C$3-IF($J4<>"",$J4,INT($B4))) | R4: =IF($A4="","",IF($O4="Closed","Closed",IF($F4="Unassigned","Unassigned",IF(AND($K4<>"",$K4<Settings!$C$3),"Overdue",IF($Q4>=Settings!$C$4,"Inactive","On Track"))))) -> Closed | S4: =IF($O4<>"Open","",IF($P4<=7,"0-7 days",IF($P4<=15,"8-15 days",IF($P4<=30,"16-30 days",IF($P4<=60,"31-60 days","60+ days"))))) | T4: =IF($A4="","",DATE(YEAR($B4),MONTH($B4),1)) -> 46174 | U4: =IF(AND($O4="Open",OR(Dashboard!$D$3="All",$F4=Dashboard!$D$3)),$H4+ROW()/100000,0) -> 0
A5: L-0004 | B5: 46175.451 | C5: LinkedIn | D5: Union Engineering | E5: Office Supplies | F5: Priya Nair | G5: Won | H5: 3800 | I5: 46175.826 | J5: 46189 | L5: 46189 | N5: =IF(OR($A5="",$I5=""),"",ROUND(($I5-$B5)*24,1)) -> 9 | O5: =IF($A5="","",IF(OR($G5="Won",$G5="Lost"),"Closed","Open")) -> Closed | P5: =IF($A5="","",IF($L5<>"",$L5,Settings!$C$3)-INT($B5)) -> 14 | Q5: =IF($O5<>"Open","",Settings!$C$3-IF($J5<>"",$J5,INT($B5))) | R5: =IF($A5="","",IF($O5="Closed","Closed",IF($F5="Unassigned","Unassigned",IF(AND($K5<>"",$K5<Settings!$C$3),"Overdue",IF($Q5>=Settings!$C$4,"Inactive","On Track"))))) -> Closed | S5: =IF($O5<>"Open","",IF($P5<=7,"0-7 days",IF($P5<=15,"8-15 days",IF($P5<=30,"16-30 days",IF($P5<=60,"31-60 days","60+ days"))))) | T5: =IF($A5="","",DATE(YEAR($B5),MONTH($B5),1)) -> 46174 | U5: =IF(AND($O5="Open",OR(Dashboard!$D$3="All",$F5=Dashboard!$D$3)),$H5+ROW()/100000,0) -> 0
A6: L-0005 | B6: 46175.66 | C6: Exhibition | D6: Prime Facility Mgmt | E6: Industrial Supplies | F6: Priya Nair | G6: Won | H6: 133200 | I6: 46175.731 | J6: 46201 | L6: 46201 | N6: =IF(OR($A6="",$I6=""),"",ROUND(($I6-$B6)*24,1)) -> 1.7 | O6: =IF($A6="","",IF(OR($G6="Won",$G6="Lost"),"Closed","Open")) -> Closed | P6: =IF($A6="","",IF($L6<>"",$L6,Settings!$C$3)-INT($B6)) -> 26 | Q6: =IF($O6<>"Open","",Settings!$C$3-IF($J6<>"",$J6,INT($B6))) | R6: =IF($A6="","",IF($O6="Closed","Closed",IF($F6="Unassigned","Unassigned",IF(AND($K6<>"",$K6<Settings!$C$3),"Overdue",IF($Q6>=Settings!$C$4,"Inactive","On Track"))))) -> Closed | S6: =IF($O6<>"Open","",IF($P6<=7,"0-7 days",IF($P6<=15,"8-15 days",IF($P6<=30,"16-30 days",IF($P6<=60,"31-60 days","60+ days"))))) | T6: =IF($A6="","",DATE(YEAR($B6),MONTH($B6),1)) -> 46174 | U6: =IF(AND($O6="Open",OR(Dashboard!$D$3="All",$F6=Dashboard!$D$3)),$H6+ROW()/100000,0) -> 0
A7: L-0006 | B7: 46177.389 | C7: Phone Call | D7: Oasis Projects LLC | E7: Plumbing & Sanitary | F7: Ahmed Hassan | G7: Lost | H7: 25800 | I7: 46177.497 | J7: 46210 | L7: 46210 | M7: No response | N7: =IF(OR($A7="",$I7=""),"",ROUND(($I7-$B7)*24,1)) -> 2.6 | O7: =IF($A7="","",IF(OR($G7="Won",$G7="Lost"),"Closed","Open")) -> Closed | P7: =IF($A7="","",IF($L7<>"",$L7,Settings!$C$3)-INT($B7)) -> 33 | Q7: =IF($O7<>"Open","",Settings!$C$3-IF($J7<>"",$J7,INT($B7))) | R7: =IF($A7="","",IF($O7="Closed","Closed",IF($F7="Unassigned","Unassigned",IF(AND($K7<>"",$K7<Settings!$C$3),"Overdue",IF($Q7>=Settings!$C$4,"Inactive","On Track"))))) -> Closed | S7: =IF($O7<>"Open","",IF($P7<=7,"0-7 days",IF($P7<=15,"8-15 days",IF($P7<=30,"16-30 days",IF($P7<=60,"31-60 days","60+ days"))))) | T7: =IF($A7="","",DATE(YEAR($B7),MONTH($B7),1)) -> 46174 | U7: =IF(AND($O7="Open",OR(Dashboard!$D$3="All",$F7=Dashboard!$D$3)),$H7+ROW()/100000,0) -> 0
A8: L-0007 | B8: 46179.347 | C8: Exhibition | D8: Union Trading LLC | E8: Electrical Items | F8: Fatima Khan | G8: Negotiation | H8: 98800 | I8: 46179.514 | J8: 46311 | K8: 46315 | N8: =IF(OR($A8="",$I8=""),"",ROUND(($I8-$B8)*24,1)) -> 4 | O8: =IF($A8="","",IF(OR($G8="Won",$G8="Lost"),"Closed","Open")) -> Open | P8: =IF($A8="","",IF($L8<>"",$L8,Settings!$C$3)-INT($B8)) -> 135 | Q8: =IF($O8<>"Open","",Settings!$C$3-IF($J8<>"",$J8,INT($B8))) -> 3 | R8: =IF($A8="","",IF($O8="Closed","Closed",IF($F8="Unassigned","Unassigned",IF(AND($K8<>"",$K8<Settings!$C$3),"Overdue",IF($Q8>=Settings!$C$4,"Inactive","On Track"))))) -> On Track | S8: =IF($O8<>"Open","",IF($P8<=7,"0-7 days",IF($P8<=15,"8-15 days",IF($P8<=30,"16-30 days",IF($P8<=60,"31-60 days","60+ days"))))) -> 60+ days | T8: =IF($A8="","",DATE(YEAR($B8),MONTH($B8),1)) -> 46174 | U8: =IF(AND($O8="Open",OR(Dashboard!$D$3="All",$F8=Dashboard!$D$3)),$H8+ROW()/100000,0) -> 98800
A9: L-0008 | B9: 46179.528 | C9: Exhibition | D9: Emirates Technical Services | E9: Plumbing & Sanitary | F9: Rahul Menon | G9: Contacted | H9: 24100 | I9: 46179.619 | J9: 46312 | K9: 46319 | N9: =IF(OR($A9="",$I9=""),"",ROUND(($I9-$B9)*24,1)) -> 2.2 | O9: =IF($A9="","",IF(OR($G9="Won",$G9="Lost"),"Closed","Open")) -> Open | P9: =IF($A9="","",IF($L9<>"",$L9,Settings!$C$3)-INT($B9)) -> 135 | Q9: =IF($O9<>"Open","",Settings!$C$3-IF($J9<>"",$J9,INT($B9))) -> 2 | R9: =IF($A9="","",IF($O9="Closed","Closed",IF($F9="Unassigned","Unassigned",IF(AND($K9<>"",$K9<Settings!$C$3),"Overdue",IF($Q9>=Settings!$C$4,"Inactive","On Track"))))) -> On Track | S9: =IF($O9<>"Open","",IF($P9<=7,"0-7 days",IF($P9<=15,"8-15 days",IF($P9<=30,"16-30 days",IF($P9<=60,"31-60 days","60+ days"))))) -> 60+ days | T9: =IF($A9="","",DATE(YEAR($B9),MONTH($B9),1)) -> 46174 | U9: =IF(AND($O9="Open",OR(Dashboard!$D$3="All",$F9=Dashboard!$D$3)),$H9+ROW()/100000,0) -> 24100
A10: L-0009 | B10: 46179.729 | C10: Email | D10: Falcon Industries | E10: Plumbing & Sanitary | F10: Priya Nair | G10: Won | H10: 108900 | I10: 46179.787 | J10: 46217 | L10: 46217 | N10: =IF(OR($A10="",$I10=""),"",ROUND(($I10-$B10)*24,1)) -> 1.4 | O10: =IF($A10="","",IF(OR($G10="Won",$G10="Lost"),"Closed","Open")) -> Closed | P10: =IF($A10="","",IF($L10<>"",$L10,Settings!$C$3)-INT($B10)) -> 38 | Q10: =IF($O10<>"Open","",Settings!$C$3-IF($J10<>"",$J10,INT($B10))) | R10: =IF($A10="","",IF($O10="Closed","Closed",IF($F10="Unassigned","Unassigned",IF(AND($K10<>"",$K10<Settings!$C$3),"Overdue",IF($Q10>=Settings!$C$4,"Inactive","On Track"))))) -> Closed | S10: =IF($O10<>"Open","",IF($P10<=7,"0-7 days",IF($P10<=15,"8-15 days",IF($P10<=30,"16-30 days",IF($P10<=60,"31-60 days","60+ days"))))) | T10: =IF($A10="","",DATE(YEAR($B10),MONTH($B10),1)) -> 46174 | U10: =IF(AND($O10="Open",OR(Dashboard!$D$3="All",$F10=Dashboard!$D$3)),$H10+ROW()/100000,0) -> 0
A11: L-0010 | B11: 46179.736 | C11: WhatsApp | D11: Horizon Construction | E11: Plumbing & Sanitary | F11: Fatima Khan | G11: Lost | H11: 10800 | I11: 46179.961 | J11: 46192 | L11: 46192 | M11: No response | N11: =IF(OR($A11="",$I11=""),"",ROUND(($I11-$B11)*24,1)) -> 5.4 | O11: =IF($A11="","",IF(OR($G11="Won",$G11="Lost"),"Closed","Open")) -> Closed | P11: =IF($A11="","",IF($L11<>"",$L11,Settings!$C$3)-INT($B11)) -> 13 | Q11: =IF($O11<>"Open","",Settings!$C$3-IF($J11<>"",$J11,INT($B11))) | R11: =IF($A11="","",IF($O11="Closed","Closed",IF($F11="Unassigned","Unassigned",IF(AND($K11<>"",$K11<Settings!$C$3),"Overdue",IF($Q11>=Settings!$C$4,"Inactive","On Track"))))) -> Closed | S11: =IF($O11<>"Open","",IF($P11<=7,"0-7 days",IF($P11<=15,"8-15 days",IF($P11<=30,"16-30 days",IF($P11<=60,"31-60 days","60+ days"))))) | T11: =IF($A11="","",DATE(YEAR($B11),MONTH($B11),1)) -> 46174 | U11: =IF(AND($O11="Open",OR(Dashboard!$D$3="All",$F11=Dashboard!$D$3)),$H11+ROW()/100000,0) -> 0
A12: L-0011 | B12: 46180.382 | C12: Walk-in | D12: Emirates Industries | E12: Plumbing & Sanitary | F12: Sara Thomas | G12: Quotation Sent | H12: 153400 | I12: 46180.724 | J12: 46312 | K12: 46320 | N12: =IF(OR($A12="",$I12=""),"",ROUND(($I12-$B12)*24,1)) -> 8.2 | O12: =IF($A12="","",IF(OR($G12="Won",$G12="Lost"),"Closed","Open")) -> Open | P12: =IF($A12="","",IF($L12<>"",$L12,Settings!$C$3)-INT($B12)) -> 134 | Q12: =IF($O12<>"Open","",Settings!$C$3-IF($J12<>"",$J12,INT($B12))) -> 2 | R12: =IF($A12="","",IF($O12="Closed","Closed",IF($F12="Unassigned","Unassigned",IF(AND($K12<>"",$K12<Settings!$C$3),"Overdue",IF($Q12>=Settings!$C$4,"Inactive","On Track"))))) -> On Track | S12: =IF($O12<>"Open","",IF($P12<=7,"0-7 days",IF($P12<=15,"8-15 days",IF($P12<=30,"16-30 days",IF($P12<=60,"31-60 days","60+ days"))))) -> 60+ days | T12: =IF($A12="","",DATE(YEAR($B12),MONTH($B12),1)) -> 46174 | U12: =IF(AND($O12="Open",OR(Dashboard!$D$3="All",$F12=Dashboard!$D$3)),$H12+ROW()/100000,0) -> 153400
A13: L-0012 | B13: 46180.417 | C13: Walk-in | D13: Gulf Projects LLC | E13: Office Supplies | F13: Omar Siddiqui | G13: Contacted | H13: 45900 | I13: 46180.958 | J13: 46311 | K13: 46316 | N13: =IF(OR($A13="",$I13=""),"",ROUND(($I13-$B13)*24,1)) -> 13 | O13: =IF($A13="","",IF(OR($G13="Won",$G13="Lost"),"Closed","Open")) -> Open | P13: =IF($A13="","",IF($L13<>"",$L13,Settings!$C$3)-INT($B13)) -> 134 | Q13: =IF($O13<>"Open","",Settings!$C$3-IF($J13<>"",$J13,INT($B13))) -> 3 | R13: =IF($A13="","",IF($O13="Closed","Closed",IF($F13="Unassigned","Unassigned",IF(AND($K13<>"",$K13<Settings!$C$3),"Overdue",IF($Q13>=Settings!$C$4,"Inactive","On Track"))))) -> On Track | S13: =IF($O13<>"Open","",IF($P13<=7,"0-7 days",IF($P13<=15,"8-15 days",IF($P13<=30,"16-30 days",IF($P13<=60,"31-60 days","60+ days"))))) -> 60+ days | T13: =IF($A13="","",DATE(YEAR($B13),MONTH($B13),1)) -> 46174 | U13: =IF(AND($O13="Open",OR(Dashboard!$D$3="All",$F13=Dashboard!$D$3)),$H13+ROW()/100000,0) -> 45900
A14: L-0013 | B14: 46180.743 | C14: Exhibition | D14: Horizon Technical Services | E14: Building Materials | F14: Sara Thomas | G14: Won | H14: 8600 | I14: 46180.835 | J14: 46212 | L14: 46212 | N14: =IF(OR($A14="",$I14=""),"",ROUND(($I14-$B14)*24,1)) -> 2.2 | O14: =IF($A14="","",IF(OR($G14="Won",$G14="Lost"),"Closed","Open")) -> Closed | P14: =IF($A14="","",IF($L14<>"",$L14,Settings!$C$3)-INT($B14)) -> 32 | Q14: =IF($O14<>"Open","",Settings!$C$3-IF($J14<>"",$J14,INT($B14))) | R14: =IF($A14="","",IF($O14="Closed","Closed",IF($F14="Unassigned","Unassigned",IF(AND($K14<>"",$K14<Settings!$C$3),"Overdue",IF($Q14>=Settings!$C$4,"Inactive","On Track"))))) -> Closed | S14: =IF($O14<>"Open","",IF($P14<=7,"0-7 days",IF($P14<=15,"8-15 days",IF($P14<=30,"16-30 days",IF($P14<=60,"31-60 days","60+ days"))))) | T14: =IF($A14="","",DATE(YEAR($B14),MONTH($B14),1)) -> 46174 | U14: =IF(AND($O14="Open",OR(Dashboard!$D$3="All",$F14=Dashboard!$D$3)),$H14+ROW()/100000,0) -> 0
A15: L-0014 | B15: 46181.347 | C15: WhatsApp | D15: Metro Engineering | E15: Building Materials | F15: Rahul Menon | G15: Won | H15: 43200 | I15: 46181.689 | J15: 46206 | L15: 46206 | N15: =IF(OR($A15="",$I15=""),"",ROUND(($I15-$B15)*24,1)) -> 8.2 | O15: =IF($A15="","",IF(OR($G15="Won",$G15="Lost"),"Closed","Open")) -> Closed | P15: =IF($A15="","",IF($L15<>"",$L15,Settings!$C$3)-INT($B15)) -> 25 | Q15: =IF($O15<>"Open","",Settings!$C$3-IF($J15<>"",$J15,INT($B15))) | R15: =IF($A15="","",IF($O15="Closed","Closed",IF($F15="Unassigned","Unassigned",IF(AND($K15<>"",$K15<Settings!$C$3),"Overdue",IF($Q15>=Settings!$C$4,"Inactive","On Track"))))) -> Closed | S15: =IF($O15<>"Open","",IF($P15<=7,"0-7 days",IF($P15<=15,"8-15 days",IF($P15<=30,"16-30 days",IF($P15<=60,"31-60 days","60+ days"))))) | T15: =IF($A15="","",DATE(YEAR($B15),MONTH($B15),1)) -> 46174 | U15: =IF(AND($O15="Open",OR(Dashboard!$D$3="All",$F15=Dashboard!$D$3)),$H15+ROW()/100000,0) -> 0
A16: L-0015 | B16: 46181.41 | C16: Email | D16: Prime Trading LLC | E16: Building Materials | F16: Ahmed Hassan | G16: Won | H16: 30400 | I16: 46181.676 | J16: 46187 | L16: 46187 | N16: =IF(OR($A16="",$I16=""),"",ROUND(($I16-$B16)*24,1)) -> 6.4 | O16: =IF($A16="","",IF(OR($G16="Won",$G16="Lost"),"Closed","Open")) -> Closed | P16: =IF($A16="","",IF($L16<>"",$L16,Settings!$C$3)-INT($B16)) -> 6 | Q16: =IF($O16<>"Open","",Settings!$C$3-IF($J16<>"",$J16,INT($B16))) | R16: =IF($A16="","",IF($O16="Closed","Closed",IF($F16="Unassigned","Unassigned",IF(AND($K16<>"",$K16<Settings!$C$3),"Overdue",IF($Q16>=Settings!$C$4,"Inactive","On Track"))))) -> Closed | S16: =IF($O16<>"Open","",IF($P16<=7,"0-7 days",IF($P16<=15,"8-15 days",IF($P16<=30,"16-30 days",IF($P16<=60,"31-60 days","60+ days"))))) | T16: =IF($A16="","",DATE(YEAR($B16),MONTH($B16),1)) -> 46174 | U16: =IF(AND($O16="Open",OR(Dashboard!$D$3="All",$F16=Dashboard!$D$3)),$H16+ROW()/100000,0) -> 0
A17: L-0016 | B17: 46181.639 | C17: WhatsApp | D17: Pearl Technical Services | E17: Electrical Items | F17: Fatima Khan | G17: Lost | H17: 45900 | I17: 46181.939 | J17: 46194 | L17: 46194 | M17: Competitor won | N17: =IF(OR($A17="",$I17=""),"",ROUND(($I17-$B17)*24,1)) -> 7.2 | O17: =IF($A17="","",IF(OR($G17="Won",$G17="Lost"),"Closed","Open")) -> Closed | P17: =IF($A17="","",IF($L17<>"",$L17,Settings!$C$3)-INT($B17)) -> 13 | Q17: =IF($O17<>"Open","",Settings!$C$3-IF($J17<>"",$J17,INT($B17))) | R17: =IF($A17="","",IF($O17="Closed","Closed",IF($F17="Unassigned","Unassigned",IF(AND($K17<>"",$K17<Settings!$C$3),"Overdue",IF($Q17>=Settings!$C$4,"Inactive","On Track"))))) -> Closed | S17: =IF($O17<>"Open","",IF($P17<=7,"0-7 days",IF($P17<=15,"8-15 days",IF($P17<=30,"16-30 days",IF($P17<=60,"31-60 days","60+ days"))))) | T17: =IF($A17="","",DATE(YEAR($B17),MONTH($B17),1)) -> 46174 | U17: =IF(AND($O17="Open",OR(Dashboard!$D$3="All",$F17=Dashboard!$D$3)),$H17+ROW()/100000,0) -> 0
A18: L-0017 | B18: 46184.34 | C18: Phone Call | D18: Skyline Construction | E18: Safety Equipment | F18: Fatima Khan | G18: Quotation Sent | H18: 225700 | I18: 46184.599 | J18: 46312 | K18: 46319 | N18: =IF(OR($A18="",$I18=""),"",ROUND(($I18-$B18)*24,1)) -> 6.2 | O18: =IF($A18="","",IF(OR($G18="Won",$G18="Lost"),"Closed","Open")) -> Open | P18: =IF($A18="","",IF($L18<>"",$L18,Settings!$C$3)-INT($B18)) -> 130 | Q18: =IF($O18<>"Open","",Settings!$C$3-IF($J18<>"",$J18,INT($B18))) -> 2 | R18: =IF($A18="","",IF($O18="Closed","Closed",IF($F18="Unassigned","Unassigned",IF(AND($K18<>"",$K18<Settings!$C$3),"Overdue",IF($Q18>=Settings!$C$4,"Inactive","On Track"))))) -> On Track | S18: =IF($O18<>"Open","",IF($P18<=7,"0-7 days",IF($P18<=15,"8-15 days",IF($P18<=30,"16-30 days",IF($P18<=60,"31-60 days","60+ days"))))) -> 60+ days | T18: =IF($A18="","",DATE(YEAR($B18),MONTH($B18),1)) -> 46174 | U18: =IF(AND($O18="Open",OR(Dashboard!$D$3="All",$F18=Dashboard!$D$3)),$H18+ROW()/100000,0) -> 225700
A19: L-0018 | B19: 46184.451 | C19: Website | D19: Desert Projects LLC | E19: Plumbing & Sanitary | F19: Omar Siddiqui | G19: Won | H19: 40000 | I19: 46186.522 | J19: 46219 | L19: 46219 | N19: =IF(OR($A19="",$I19=""),"",ROUND(($I19-$B19)*24,1)) -> 49.7 | O19: =IF($A19="","",IF(OR($G19="Won",$G19="Lost"),"Closed","Open")) -> Closed | P19: =IF($A19="","",IF($L19<>"",$L19,Settings!$C$3)-INT($B19)) -> 35 | Q19: =IF($O19<>"Open","",Settings!$C$3-IF($J19<>"",$J19,INT($B19))) | R19: =IF($A19="","",IF($O19="Closed","Closed",IF($F19="Unassigned","Unassigned",IF(AND($K19<>"",$K19<Settings!$C$3),"Overdue",IF($Q19>=Settings!$C$4,"Inactive","On Track"))))) -> Closed | S19: =IF($O19<>"Open","",IF($P19<=7,"0-7 days",IF($P19<=15,"8-15 days",IF($P19<=30,"16-30 days",IF($P19<=60,"31-60 days","60+ days"))))) | T19: =IF($A19="","",DATE(YEAR($B19),MONTH($B19),1)) -> 46174 | U19: =IF(AND($O19="Open",OR(Dashboard!$D$3="All",$F19=Dashboard!$D$3)),$H19+ROW()/100000,0) -> 0
A20: L-0019 | B20: 46184.549 | C20: WhatsApp | D20: Gulf Trading LLC | E20: Safety Equipment | F20: Sara Thomas | G20: Won | H20: 46300 | I20: 46184.699 | J20: 46189 | L20: 46189 | N20: =IF(OR($A20="",$I20=""),"",ROUND(($I20-$B20)*24,1)) -> 3.6 | O20: =IF($A20="","",IF(OR($G20="Won",$G20="Lost"),"Closed","Open")) -> Closed | P20: =IF($A20="","",IF($L20<>"",$L20,Settings!$C$3)-INT($B20)) -> 5 | Q20: =IF($O20<>"Open","",Settings!$C$3-IF($J20<>"",$J20,INT($B20))) | R20: =IF($A20="","",IF($O20="Closed","Closed",IF($F20="Unassigned","Unassigned",IF(AND($K20<>"",$K20<Settings!$C$3),"Overdue",IF($Q20>=Settings!$C$4,"Inactive","On Track"))))) -> Closed | S20: =IF($O20<>"Open","",IF($P20<=7,"0-7 days",IF($P20<=15,"8-15 days",IF($P20<=30,"16-30 days",IF($P20<=60,"31-60 days","60+ days"))))) | T20: =IF($A20="","",DATE(YEAR($B20),MONTH($B20),1)) -> 46174 | U20: =IF(AND($O20="Open",OR(Dashboard!$D$3="All",$F20=Dashboard!$D$3)),$H20+ROW()/100000,0) -> 0
A21: L-0020 | B21: 46184.618 | C21: Phone Call | D21: Metro Facility Mgmt | E21: Building Materials | F21: Omar Siddiqui | G21: Lost | H21: 48900 | I21: 46185.11 | J21: 46220 | L21: 46220 | M21: Competitor won | N21: =IF(OR($A21="",$I21=""),"",ROUND(($I21-$B21)*24,1)) -> 11.8 | O21: =IF($A21="","",IF(OR($G21="Won",$G21="Lost"),"Closed","Open")) -> Closed | P21: =IF($A21="","",IF($L21<>"",$L21,Settings!$C$3)-INT($B21)) -> 36 | Q21: =IF($O21<>"Open","",Settings!$C$3-IF($J21<>"",$J21,INT($B21))) | R21: =IF($A21="","",IF($O21="Closed","Closed",IF($F21="Unassigned","Unassigned",IF(AND($K21<>"",$K21<Settings!$C$3),"Overdue",IF($Q21>=Settings!$C$4,"Inactive","On Track"))))) -> Closed | S21: =IF($O21<>"Open","",IF($P21<=7,"0-7 days",IF($P21<=15,"8-15 days",IF($P21<=30,"16-30 days",IF($P21<=60,"31-60 days","60+ days"))))) | T21: =IF($A21="","",DATE(YEAR($B21),MONTH($B21),1)) -> 46174 | U21: =IF(AND($O21="Open",OR(Dashboard!$D$3="All",$F21=Dashboard!$D$3)),$H21+ROW()/100000,0) -> 0
A22: L-0021 | B22: 46185.521 | C22: Phone Call | D22: Emirates Trading LLC | E22: Safety Equipment | F22: Rahul Menon | G22: Won | H22: 5200 | I22: 46185.708 | J22: 46197 | L22: 46197 | N22: =IF(OR($A22="",$I22=""),"",ROUND(($I22-$B22)*24,1)) -> 4.5 | O22: =IF($A22="","",IF(OR($G22="Won",$G22="Lost"),"Closed","Open")) -> Closed | P22: =IF($A22="","",IF($L22<>"",$L22,Settings!$C$3)-INT($B22)) -> 12 | Q22: =IF($O22<>"Open","",Settings!$C$3-IF($J22<>"",$J22,INT($B22))) | R22: =IF($A22="","",IF($O22="Closed","Closed",IF($F22="Unassigned","Unassigned",IF(AND($K22<>"",$K22<Settings!$C$3),"Overdue",IF($Q22>=Settings!$C$4,"Inactive","On Track"))))) -> Closed | S22: =IF($O22<>"Open","",IF($P22<=7,"0-7 days",IF($P22<=15,"8-15 days",IF($P22<=30,"16-30 days",IF($P22<=60,"31-60 days","60+ days"))))) | T22: =IF($A22="","",DATE(YEAR($B22),MONTH($B22),1)) -> 46174 | U22: =IF(AND($O22="Open",OR(Dashboard!$D$3="All",$F22=Dashboard!$D$3)),$H22+ROW()/100000,0) -> 0
A23: L-0022 | B23: 46185.681 | C23: WhatsApp | D23: Prime Technical Services | E23: Plumbing & Sanitary | F23: Sara Thomas | G23: Quotation Sent | H23: 177700 | I23: 46186.601 | J23: 46309 | K23: 46313 | N23: =IF(OR($A23="",$I23=""),"",ROUND(($I23-$B23)*24,1)) -> 22.1 | O23: =IF($A23="","",IF(OR($G23="Won",$G23="Lost"),"Closed","Open")) -> Open | P23: =IF($A23="","",IF($L23<>"",$L23,Settings!$C$3)-INT($B23)) -> 129 | Q23: =IF($O23<>"Open","",Settings!$C$3-IF($J23<>"",$J23,INT($B23))) -> 5 | R23: =IF($A23="","",IF($O23="Closed","Closed",IF($F23="Unassigned","Unassigned",IF(AND($K23<>"",$K23<Settings!$C$3),"Overdue",IF($Q23>=Settings!$C$4,"Inactive","On Track"))))) -> Overdue | S23: =IF($O23<>"Open","",IF($P23<=7,"0-7 days",IF($P23<=15,"8-15 days",IF($P23<=30,"16-30 days",IF($P23<=60,"31-60 days","60+ days"))))) -> 60+ days | T23: =IF($A23="","",DATE(YEAR($B23),MONTH($B23),1)) -> 46174 | U23: =IF(AND($O23="Open",OR(Dashboard!$D$3="All",$F23=Dashboard!$D$3)),$H23+ROW()/100000,0) -> 177700
A24: L-0023 | B24: 46186.389 | C24: Walk-in | D24: Prime Engineering | E24: Building Materials | F24: Priya Nair | G24: Lost | H24: 58500 | I24: 46186.489 | J24: 46208 | L24: 46208 | M24: No response | N24: =IF(OR($A24="",$I24=""),"",ROUND(($I24-$B24)*24,1)) -> 2.4 | O24: =IF($A24="","",IF(OR($G24="Won",$G24="Lost"),"Closed","Open")) -> Closed | P24: =IF($A24="","",IF($L24<>"",$L24,Settings!$C$3)-INT($B24)) -> 22 | Q24: =IF($O24<>"Open","",Settings!$C$3-IF($J24<>"",$J24,INT($B24))) | R24: =IF($A24="","",IF($O24="Closed","Closed",IF($F24="Unassigned","Unassigned",IF(AND($K24<>"",$K24<Settings!$C$3),"Overdue",IF($Q24>=Settings!$C$4,"Inactive","On Track"))))) -> Closed | S24: =IF($O24<>"Open","",IF($P24<=7,"0-7 days",IF($P24<=15,"8-15 days",IF($P24<=30,"16-30 days",IF($P24<=60,"31-60 days","60+ days"))))) | T24: =IF($A24="","",DATE(YEAR($B24),MONTH($B24),1)) -> 46174 | U24: =IF(AND($O24="Open",OR(Dashboard!$D$3="All",$F24=Dashboard!$D$3)),$H24+ROW()/100000,0) -> 0
A25: L-0024 | B25: 46186.743 | C25: Phone Call | D25: Prime Projects LLC | E25: Office Supplies | F25: Priya Nair | G25: Negotiation | H25: 21800 | I25: 46186.914 | J25: 46313 | K25: 46320 | N25: =IF(OR($A25="",$I25=""),"",ROUND(($I25-$B25)*24,1)) -> 4.1 | O25: =IF($A25="","",IF(OR($G25="Won",$G25="Lost"),"Closed","Open")) -> Open | P25: =IF($A25="","",IF($L25<>"",$L25,Settings!$C$3)-INT($B25)) -> 128 | Q25: =IF($O25<>"Open","",Settings!$C$3-IF($J25<>"",$J25,INT($B25))) -> 1 | R25: =IF($A25="","",IF($O25="Closed","Closed",IF($F25="Unassigned","Unassigned",IF(AND($K25<>"",$K25<Settings!$C$3),"Overdue",IF($Q25>=Settings!$C$4,"Inactive","On Track"))))) -> On Track | S25: =IF($O25<>"Open","",IF($P25<=7,"0-7 days",IF($P25<=15,"8-15 days",IF($P25<=30,"16-30 days",IF($P25<=60,"31-60 days","60+ days"))))) -> 60+ days | T25: =IF($A25="","",DATE(YEAR($B25),MONTH($B25),1)) -> 46174 | U25: =IF(AND($O25="Open",OR(Dashboard!$D$3="All",$F25=Dashboard!$D$3)),$H25+ROW()/100000,0) -> 21800
A26: L-0025 | B26: 46187.424 | C26: Referral | D26: Pearl Construction | E26: Office Supplies | F26: Ahmed Hassan | G26: Contacted | H26: 68300 | I26: 46187.769 | J26: 46306 | K26: 46311 | N26: =IF(OR($A26="",$I26=""),"",ROUND(($I26-$B26)*24,1)) -> 8.3 | O26: =IF($A26="","",IF(OR($G26="Won",$G26="Lost"),"Closed","Open")) -> Open | P26: =IF($A26="","",IF($L26<>"",$L26,Settings!$C$3)-INT($B26)) -> 127 | Q26: =IF($O26<>"Open","",Settings!$C$3-IF($J26<>"",$J26,INT($B26))) -> 8 | R26: =IF($A26="","",IF($O26="Closed","Closed",IF($F26="Unassigned","Unassigned",IF(AND($K26<>"",$K26<Settings!$C$3),"Overdue",IF($Q26>=Settings!$C$4,"Inactive","On Track"))))) -> Overdue | S26: =IF($O26<>"Open","",IF($P26<=7,"0-7 days",IF($P26<=15,"8-15 days",IF($P26<=30,"16-30 days",IF($P26<=60,"31-60 days","60+ days"))))) -> 60+ days | T26: =IF($A26="","",DATE(YEAR($B26),MONTH($B26),1)) -> 46174 | U26: =IF(AND($O26="Open",OR(Dashboard!$D$3="All",$F26=Dashboard!$D$3)),$H26+ROW()/100000,0) -> 68300
A27: L-0026 | B27: 46189.625 | C27: Referral | D27: Metro Projects LLC | E27: Electrical Items | F27: Omar Siddiqui | G27: Contacted | H27: 12600 | I27: 46190.137 | J27: 46302 | K27: 46310 | N27: =IF(OR($A27="",$I27=""),"",ROUND(($I27-$B27)*24,1)) -> 12.3 | O27: =IF($A27="","",IF(OR($G27="Won",$G27="Lost"),"Closed","Open")) -> Open | P27: =IF($A27="","",IF($L27<>"",$L27,Settings!$C$3)-INT($B27)) -> 125 | Q27: =IF($O27<>"Open","",Settings!$C$3-IF($J27<>"",$J27,INT($B27))) -> 12 | R27: =IF($A27="","",IF($O27="Closed","Closed",IF($F27="Unassigned","Unassigned",IF(AND($K27<>"",$K27<Settings!$C$3),"Overdue",IF($Q27>=Settings!$C$4,"Inactive","On Track"))))) -> Overdue | S27: =IF($O27<>"Open","",IF($P27<=7,"0-7 days",IF($P27<=15,"8-15 days",IF($P27<=30,"16-30 days",IF($P27<=60,"31-60 days","60+ days"))))) -> 60+ days | T27: =IF($A27="","",DATE(YEAR($B27),MONTH($B27),1)) -> 46174 | U27: =IF(AND($O27="Open",OR(Dashboard!$D$3="All",$F27=Dashboard!$D$3)),$H27+ROW()/100000,0) -> 12600
A28: L-0027 | B28: 46190.486 | C28: Website | D28: Horizon Facility Mgmt | E28: Industrial Supplies | F28: Sara Thomas | G28: Lost | H28: 9100 | I28: 46190.582 | J28: 46219 | L28: 46219 | M28: Price too high | N28: =IF(OR($A28="",$I28=""),"",ROUND(($I28-$B28)*24,1)) -> 2.3 | O28: =IF($A28="","",IF(OR($G28="Won",$G28="Lost"),"Closed","Open")) -> Closed | P28: =IF($A28="","",IF($L28<>"",$L28,Settings!$C$3)-INT($B28)) -> 29 | Q28: =IF($O28<>"Open","",Settings!$C$3-IF($J28<>"",$J28,INT($B28))) | R28: =IF($A28="","",IF($O28="Closed","Closed",IF($F28="Unassigned","Unassigned",IF(AND($K28<>"",$K28<Settings!$C$3),"Overdue",IF($Q28>=Settings!$C$4,"Inactive","On Track"))))) -> Closed | S28: =IF($O28<>"Open","",IF($P28<=7,"0-7 days",IF($P28<=15,"8-15 days",IF($P28<=30,"16-30 days",IF($P28<=60,"31-60 days","60+ days"))))) | T28: =IF($A28="","",DATE(YEAR($B28),MONTH($B28),1)) -> 46174 | U28: =IF(AND($O28="Open",OR(Dashboard!$D$3="All",$F28=Dashboard!$D$3)),$H28+ROW()/100000,0) -> 0
A29: L-0028 | B29: 46190.604 | C29: Referral | D29: Pearl Projects LLC | E29: Office Supplies | F29: Rahul Menon | G29: Lost | H29: 16600 | I29: 46191.079 | J29: 46227 | L29: 46227 | M29: Price too high | N29: =IF(OR($A29="",$I29=""),"",ROUND(($I29-$B29)*24,1)) -> 11.4 | O29: =IF($A29="","",IF(OR($G29="Won",$G29="Lost"),"Closed","Open")) -> Closed | P29: =IF($A29="","",IF($L29<>"",$L29,Settings!$C$3)-INT($B29)) -> 37 | Q29: =IF($O29<>"Open","",Settings!$C$3-IF($J29<>"",$J29,INT($B29))) | R29: =IF($A29="","",IF($O29="Closed","Closed",IF($F29="Unassigned","Unassigned",IF(AND($K29<>"",$K29<Settings!$C$3),"Overdue",IF($Q29>=Settings!$C$4,"Inactive","On Track"))))) -> Closed | S29: =IF($O29<>"Open","",IF($P29<=7,"0-7 days",IF($P29<=15,"8-15 days",IF($P29<=30,"16-30 days",IF($P29<=60,"31-60 days","60+ days"))))) | T29: =IF($A29="","",DATE(YEAR($B29),MONTH($B29),1)) -> 46174 | U29: =IF(AND($O29="Open",OR(Dashboard!$D$3="All",$F29=Dashboard!$D$3)),$H29+ROW()/100000,0) -> 0
A30: L-0029 | B30: 46191.347 | C30: WhatsApp | D30: Horizon Projects LLC | E30: Plumbing & Sanitary | F30: Rahul Menon | G30: Lost | H30: 6500 | I30: 46191.493 | J30: 46228 | L30: 46228 | M30: Competitor won | N30: =IF(OR($A30="",$I30=""),"",ROUND(($I30-$B30)*24,1)) -> 3.5 | O30: =IF($A30="","",IF(OR($G30="Won",$G30="Lost"),"Closed","Open")) -> Closed | P30: =IF($A30="","",IF($L30<>"",$L30,Settings!$C$3)-INT($B30)) -> 37 | Q30: =IF($O30<>"Open","",Settings!$C$3-IF($J30<>"",$J30,INT($B30))) | R30: =IF($A30="","",IF($O30="Closed","Closed",IF($F30="Unassigned","Unassigned",IF(AND($K30<>"",$K30<Settings!$C$3),"Overdue",IF($Q30>=Settings!$C$4,"Inactive","On Track"))))) -> Closed | S30: =IF($O30<>"Open","",IF($P30<=7,"0-7 days",IF($P30<=15,"8-15 days",IF($P30<=30,"16-30 days",IF($P30<=60,"31-60 days","60+ days"))))) | T30: =IF($A30="","",DATE(YEAR($B30),MONTH($B30),1)) -> 46174 | U30: =IF(AND($O30="Open",OR(Dashboard!$D$3="All",$F30=Dashboard!$D$3)),$H30+ROW()/100000,0) -> 0
A31: L-0030 | B31: 46191.493 | C31: Exhibition | D31: Royal Construction | E31: Plumbing & Sanitary | F31: Omar Siddiqui | G31: Lost | H31: 131800 | I31: 46191.768 | J31: 46211 | L31: 46211 | M31: No response | N31: =IF(OR($A31="",$I31=""),"",ROUND(($I31-$B31)*24,1)) -> 6.6 | O31: =IF($A31="","",IF(OR($G31="Won",$G31="Lost"),"Closed","Open")) -> Closed | P31: =IF($A31="","",IF($L31<>"",$L31,Settings!$C$3)-INT($B31)) -> 20 | Q31: =IF($O31<>"Open","",Settings!$C$3-IF($J31<>"",$J31,INT($B31))) | R31: =IF($A31="","",IF($O31="Closed","Closed",IF($F31="Unassigned","Unassigned",IF(AND($K31<>"",$K31<Settings!$C$3),"Overdue",IF($Q31>=Settings!$C$4,"Inactive","On Track"))))) -> Closed | S31: =IF($O31<>"Open","",IF($P31<=7,"0-7 days",IF($P31<=15,"8-15 days",IF($P31<=30,"16-30 days",IF($P31<=60,"31-60 days","60+ days"))))) | T31: =IF($A31="","",DATE(YEAR($B31),MONTH($B31),1)) -> 46174 | U31: =IF(AND($O31="Open",OR(Dashboard!$D$3="All",$F31=Dashboard!$D$3)),$H31+ROW()/100000,0) -> 0
A32: L-0031 | B32: 46191.549 | C32: WhatsApp | D32: Desert Construction | E32: Office Supplies | F32: Sara Thomas | G32: Lost | H32: 42300 | I32: 46191.69 | J32: 46211 | L32: 46211 | M32: Competitor won | N32: =IF(OR($A32="",$I32=""),"",ROUND(($I32-$B32)*24,1)) -> 3.4 | O32: =IF($A32="","",IF(OR($G32="Won",$G32="Lost"),"Closed","Open")) -> Closed | P32: =IF($A32="","",IF($L32<>"",$L32,Settings!$C$3)-INT($B32)) -> 20 | Q32: =IF($O32<>"Open","",Settings!$C$3-IF($J32<>"",$J32,INT($B32))) | R32: =IF($A32="","",IF($O32="Closed","Closed",IF($F32="Unassigned","Unassigned",IF(AND($K32<>"",$K32<Settings!$C$3),"Overdue",IF($Q32>=Settings!$C$4,"Inactive","On Track"))))) -> Closed | S32: =IF($O32<>"Open","",IF($P32<=7,"0-7 days",IF($P32<=15,"8-15 days",IF($P32<=30,"16-30 days",IF($P32<=60,"31-60 days","60+ days"))))) | T32: =IF($A32="","",DATE(YEAR($B32),MONTH($B32),1)) -> 46174 | U32: =IF(AND($O32="Open",OR(Dashboard!$D$3="All",$F32=Dashboard!$D$3)),$H32+ROW()/100000,0) -> 0
A33: L-0032 | B33: 46192.444 | C33: Walk-in | D33: Apex Technical Services | E33: Building Materials | F33: Sara Thomas | G33: Won | H33: 107000 | I33: 46192.582 | J33: 46200 | L33: 46200 | N33: =IF(OR($A33="",$I33=""),"",ROUND(($I33-$B33)*24,1)) -> 3.3 | O33: =IF($A33="","",IF(OR($G33="Won",$G33="Lost"),"Closed","Open")) -> Closed | P33: =IF($A33="","",IF($L33<>"",$L33,Settings!$C$3)-INT($B33)) -> 8 | Q33: =IF($O33<>"Open","",Settings!$C$3-IF($J33<>"",$J33,INT($B33))) | R33: =IF($A33="","",IF($O33="Closed","Closed",IF($F33="Unassigned","Unassigned",IF(AND($K33<>"",$K33<Settings!$C$3),"Overdue",IF($Q33>=Settings!$C$4,"Inactive","On Track"))))) -> Closed | S33: =IF($O33<>"Open","",IF($P33<=7,"0-7 days",IF($P33<=15,"8-15 days",IF($P33<=30,"16-30 days",IF($P33<=60,"31-60 days","60+ days"))))) | T33: =IF($A33="","",DATE(YEAR($B33),MONTH($B33),1)) -> 46174 | U33: =IF(AND($O33="Open",OR(Dashboard!$D$3="All",$F33=Dashboard!$D$3)),$H33+ROW()/100000,0) -> 0
A34: L-0033 | B34: 46193.653 | C34: WhatsApp | D34: Royal Projects LLC | E34: Electrical Items | F34: Rahul Menon | G34: Won | H34: 40700 | I34: 46193.699 | J34: 46233 | L34: 46233 | N34: =IF(OR($A34="",$I34=""),"",ROUND(($I34-$B34)*24,1)) -> 1.1 | O34: =IF($A34="","",IF(OR($G34="Won",$G34="Lost"),"Closed","Open")) -> Closed | P34: =IF($A34="","",IF($L34<>"",$L34,Settings!$C$3)-INT($B34)) -> 40 | Q34: =IF($O34<>"Open","",Settings!$C$3-IF($J34<>"",$J34,INT($B34))) | R34: =IF($A34="","",IF($O34="Closed","Closed",IF($F34="Unassigned","Unassigned",IF(AND($K34<>"",$K34<Settings!$C$3),"Overdue",IF($Q34>=Settings!$C$4,"Inactive","On Track"))))) -> Closed | S34: =IF($O34<>"Open","",IF($P34<=7,"0-7 days",IF($P34<=15,"8-15 days",IF($P34<=30,"16-30 days",IF($P34<=60,"31-60 days","60+ days"))))) | T34: =IF($A34="","",DATE(YEAR($B34),MONTH($B34),1)) -> 46174 | U34: =IF(AND($O34="Open",OR(Dashboard!$D$3="All",$F34=Dashboard!$D$3)),$H34+ROW()/100000,0) -> 0
A35: L-0034 | B35: 46194.347 | C35: WhatsApp | D35: Gulf Facility Mgmt | E35: Office Supplies | F35: Fatima Khan | G35: Quotation Sent | H35: 81600 | I35: 46194.485 | J35: 46311 | K35: 46320 | N35: =IF(OR($A35="",$I35=""),"",ROUND(($I35-$B35)*24,1)) -> 3.3 | O35: =IF($A35="","",IF(OR($G35="Won",$G35="Lost"),"Closed","Open")) -> Open | P35: =IF($A35="","",IF($L35<>"",$L35,Settings!$C$3)-INT($B35)) -> 120 | Q35: =IF($O35<>"Open","",Settings!$C$3-IF($J35<>"",$J35,INT($B35))) -> 3 | R35: =IF($A35="","",IF($O35="Closed","Closed",IF($F35="Unassigned","Unassigned",IF(AND($K35<>"",$K35<Settings!$C$3),"Overdue",IF($Q35>=Settings!$C$4,"Inactive","On Track"))))) -> On Track | S35: =IF($O35<>"Open","",IF($P35<=7,"0-7 days",IF($P35<=15,"8-15 days",IF($P35<=30,"16-30 days",IF($P35<=60,"31-60 days","60+ days"))))) -> 60+ days | T35: =IF($A35="","",DATE(YEAR($B35),MONTH($B35),1)) -> 46174 | U35: =IF(AND($O35="Open",OR(Dashboard!$D$3="All",$F35=Dashboard!$D$3)),$H35+ROW()/100000,0) -> 81600
A36: L-0035 | B36: 46194.41 | C36: Website | D36: Sahara Engineering | E36: Industrial Supplies | F36: Priya Nair | G36: Negotiation | H36: 293300 | I36: 46194.447 | J36: 46296 | K36: 46305 | N36: =IF(OR($A36="",$I36=""),"",ROUND(($I36-$B36)*24,1)) -> 0.9 | O36: =IF($A36="","",IF(OR($G36="Won",$G36="Lost"),"Closed","Open")) -> Open | P36: =IF($A36="","",IF($L36<>"",$L36,Settings!$C$3)-INT($B36)) -> 120 | Q36: =IF($O36<>"Open","",Settings!$C$3-IF($J36<>"",$J36,INT($B36))) -> 18 | R36: =IF($A36="","",IF($O36="Closed","Closed",IF($F36="Unassigned","Unassigned",IF(AND($K36<>"",$K36<Settings!$C$3),"Overdue",IF($Q36>=Settings!$C$4,"Inactive","On Track"))))) -> Overdue | S36: =IF($O36<>"Open","",IF($P36<=7,"0-7 days",IF($P36<=15,"8-15 days",IF($P36<=30,"16-30 days",IF($P36<=60,"31-60 days","60+ days"))))) -> 60+ days | T36: =IF($A36="","",DATE(YEAR($B36),MONTH($B36),1)) -> 46174 | U36: =IF(AND($O36="Open",OR(Dashboard!$D$3="All",$F36=Dashboard!$D$3)),$H36+ROW()/100000,0) -> 293300
A37: L-0036 | B37: 46194.618 | C37: Phone Call | D37: Falcon Construction | E37: Building Materials | F37: Ahmed Hassan | G37: Lost | H37: 17700 | I37: 46194.831 | J37: 46202 | L37: 46202 | M37: No response | N37: =IF(OR($A37="",$I37=""),"",ROUND(($I37-$B37)*24,1)) -> 5.1 | O37: =IF($A37="","",IF(OR($G37="Won",$G37="Lost"),"Closed","Open")) -> Closed | P37: =IF($A37="","",IF($L37<>"",$L37,Settings!$C$3)-INT($B37)) -> 8 | Q37: =IF($O37<>"Open","",Settings!$C$3-IF($J37<>"",$J37,INT($B37))) | R37: =IF($A37="","",IF($O37="Closed","Closed",IF($F37="Unassigned","Unassigned",IF(AND($K37<>"",$K37<Settings!$C$3),"Overdue",IF($Q37>=Settings!$C$4,"Inactive","On Track"))))) -> Closed | S37: =IF($O37<>"Open","",IF($P37<=7,"0-7 days",IF($P37<=15,"8-15 days",IF($P37<=30,"16-30 days",IF($P37<=60,"31-60 days","60+ days"))))) | T37: =IF($A37="","",DATE(YEAR($B37),MONTH($B37),1)) -> 46174 | U37: =IF(AND($O37="Open",OR(Dashboard!$D$3="All",$F37=Dashboard!$D$3)),$H37+ROW()/100000,0) -> 0
A38: L-0037 | B38: 46195.681 | C38: WhatsApp | D38: Royal Contracting LLC | E38: Electrical Items | F38: Rahul Menon | G38: Quotation Sent | H38: 7300 | I38: 46195.71 | J38: 46296 | K38: 46302 | N38: =IF(OR($A38="",$I38=""),"",ROUND(($I38-$B38)*24,1)) -> 0.7 | O38: =IF($A38="","",IF(OR($G38="Won",$G38="Lost"),"Closed","Open")) -> Open | P38: =IF($A38="","",IF($L38<>"",$L38,Settings!$C$3)-INT($B38)) -> 119 | Q38: =IF($O38<>"Open","",Settings!$C$3-IF($J38<>"",$J38,INT($B38))) -> 18 | R38: =IF($A38="","",IF($O38="Closed","Closed",IF($F38="Unassigned","Unassigned",IF(AND($K38<>"",$K38<Settings!$C$3),"Overdue",IF($Q38>=Settings!$C$4,"Inactive","On Track"))))) -> Overdue | S38: =IF($O38<>"Open","",IF($P38<=7,"0-7 days",IF($P38<=15,"8-15 days",IF($P38<=30,"16-30 days",IF($P38<=60,"31-60 days","60+ days"))))) -> 60+ days | T38: =IF($A38="","",DATE(YEAR($B38),MONTH($B38),1)) -> 46174 | U38: =IF(AND($O38="Open",OR(Dashboard!$D$3="All",$F38=Dashboard!$D$3)),$H38+ROW()/100000,0) -> 7300.0004
A39: L-0038 | B39: 46196.583 | C39: LinkedIn | D39: Gulf Construction | E39: Plumbing & Sanitary | F39: Fatima Khan | G39: Lost | H39: 66100 | I39: 46198.067 | J39: 46222 | L39: 46222 | M39: Competitor won | N39: =IF(OR($A39="",$I39=""),"",ROUND(($I39-$B39)*24,1)) -> 35.6 | O39: =IF($A39="","",IF(OR($G39="Won",$G39="Lost"),"Closed","Open")) -> Closed | P39: =IF($A39="","",IF($L39<>"",$L39,Settings!$C$3)-INT($B39)) -> 26 | Q39: =IF($O39<>"Open","",Settings!$C$3-IF($J39<>"",$J39,INT($B39))) | R39: =IF($A39="","",IF($O39="Closed","Closed",IF($F39="Unassigned","Unassigned",IF(AND($K39<>"",$K39<Settings!$C$3),"Overdue",IF($Q39>=Settings!$C$4,"Inactive","On Track"))))) -> Closed | S39: =IF($O39<>"Open","",IF($P39<=7,"0-7 days",IF($P39<=15,"8-15 days",IF($P39<=30,"16-30 days",IF($P39<=60,"31-60 days","60+ days"))))) | T39: =IF($A39="","",DATE(YEAR($B39),MONTH($B39),1)) -> 46174 | U39: =IF(AND($O39="Open",OR(Dashboard!$D$3="All",$F39=Dashboard!$D$3)),$H39+ROW()/100000,0) -> 0
A40: L-0039 | B40: 46197.458 | C40: Email | D40: Apex Engineering | E40: Plumbing & Sanitary | F40: Priya Nair | G40: Quotation Sent | H40: 17200 | I40: 46197.533 | J40: 46311 | K40: 46317 | N40: =IF(OR($A40="",$I40=""),"",ROUND(($I40-$B40)*24,1)) -> 1.8 | O40: =IF($A40="","",IF(OR($G40="Won",$G40="Lost"),"Closed","Open")) -> Open | P40: =IF($A40="","",IF($L40<>"",$L40,Settings!$C$3)-INT($B40)) -> 117 | Q40: =IF($O40<>"Open","",Settings!$C$3-IF($J40<>"",$J40,INT($B40))) -> 3 | R40: =IF($A40="","",IF($O40="Closed","Closed",IF($F40="Unassigned","Unassigned",IF(AND($K40<>"",$K40<Settings!$C$3),"Overdue",IF($Q40>=Settings!$C$4,"Inactive","On Track"))))) -> On Track | S40: =IF($O40<>"Open","",IF($P40<=7,"0-7 days",IF($P40<=15,"8-15 days",IF($P40<=30,"16-30 days",IF($P40<=60,"31-60 days","60+ days"))))) -> 60+ days | T40: =IF($A40="","",DATE(YEAR($B40),MONTH($B40),1)) -> 46174 | U40: =IF(AND($O40="Open",OR(Dashboard!$D$3="All",$F40=Dashboard!$D$3)),$H40+ROW()/100000,0) -> 17200
...

Sheet Settings
B2: Settings & Lists
B3: As-of date (reporting date) | C3: 46314
B4: Inactive threshold (days since last contact) | C4: 7 | D4: Open leads with no contact for this many days are flagged Inactive.
B6: Drop-down lists used by the Lead_Data sheet and Dashboard filter.
B8: Executives | C8: Lead Source | D8: Status | E8: Requirement | F8: Lost Reason | G8: Dashboard Filter
B9: Rahul Menon | C9: Website | D9: New | E9: Industrial Supplies | F9: Price too high | G9: All
B10: Fatima Khan | C10: WhatsApp | D10: Contacted | E10: Electrical Items | F10: Competitor won | G10: Rahul Menon
B11: Omar Siddiqui | C11: Phone Call | D11: Quotation Sent | E11: Building Materials | F11: No response | G11: Fatima Khan
B12: Priya Nair | C12: Walk-in | D12: Negotiation | E12: Safety Equipment | F12: Requirement cancelled | G12: Omar Siddiqui
B13: Ahmed Hassan | C13: Referral | D13: Won | E13: Plumbing & Sanitary | F13: Delivery time | G13: Priya Nair
B14: Sara Thomas | C14: Exhibition | D14: Lost | E14: Office Supplies | F14: Out of stock | G14: Ahmed Hassan
B15: Unassigned | C15: LinkedIn | G15: Sara Thomas
C16: Email | G16: Unassigned
